<?xml version="1.0" ?>
<!-- =================================================================================== -->
<!-- |    This document was autogenerated by xacro from robot.urdf.xacro               | -->
<!-- |    EDITING THIS FILE BY HAND IS NOT RECOMMENDED                                 | -->
<!-- =================================================================================== -->
<?xml version="1.0"?>
<!-- robot_core.xacro -->
<robot xmlns:xacro="http://www.ros.org/wiki/xacro">

    <xacro:include filename="inertial_macros.xacro" />
    <xacro:include filename="lidar.xacro" />
    <xacro:arg name="mesh_enabled" default="false" />
    <xacro:arg name="robot_namespace" default="/" />

    <material name="white">
        <color rgba="1 1 1 1" />
    </material>

    <material name="orange">
        <color rgba="1 0.3 0.1 1" />
    </material>

    <material name="blue">
        <color rgba="0.2 0.2 1 1" />
    </material>

    <material name="black">
        <color rgba="0 0 0 1" />
    </material>

    <!-- BASE LINK -->

    <link name="base_link">

    </link>


    <!-- CHASSIS LINK -->

    <joint name="chassis_joint" type="fixed">
        <parent link="base_link" />
        <child link="chassis" />
        <origin xyz="0 0 0" rpy="0 0 0"/>
    </joint>

    <link name="chassis">
        <visual>
            <geometry>
              <mesh filename="package://mobile_03668/STL/Chassis.STL" scale="0.001 0.001 0.001"/>
            </geometry>
            <origin xyz="-0.05 -0.1 -0.016" rpy="1.57 0 1.57"/>
            <material name="white"/>
        </visual>
        <!--<collision>
            <origin xyz="0.15 0 0.075" />
            <geometry>
                <box size="0.3 0.3 0.15" />
            </geometry>
        </collision> -->
        <xacro:inertial_box mass="0.5" x="0.3" y="0.3" z="0.15">
            <origin xyz="0 0 0" rpy="1.57 0 1.57"/>
        </xacro:inertial_box>
    </link>

    <!-- Jetson -->

    <joint name="Jetson_joint" type="fixed">
        <parent link="chassis" />
        <child link="Jetson" />
        <origin xyz="0 0 0.145" rpy="0 0 0"/>
    </joint>

    <link name="Jetson">
        <visual>
            <geometry>
              <mesh filename="package://mobile_03668/STL/Jetson.STL" scale="0.001 0.001 0.001"/>
            </geometry>
            <origin xyz="-0.035 -0.045 -0.025" rpy="0 0 0"/>
            <material name="blue"/>
        </visual>
        <!--<collision>
            <origin xyz="0.15 0 0.075" />
            <geometry>
                <box size="0.3 0.3 0.15" />
            </geometry>
        </collision> -->
        <xacro:inertial_box mass="0.5" x="0.3" y="0.3" z="0.15">
            <origin xyz="-0.06 0.05 0.122" rpy="0 0 0"/>
        </xacro:inertial_box>
    </link>

    <!-- LEFT WHEEL LINK -->

    <joint name="left_wheel" type="continuous">
        <parent link="base_link" />
        <child link="left_wheel_link" />
        <origin xyz="0.005 0.085 0.030" rpy="0 0 1.57"/>
        <dynamics damping="0.5" friction="100.0" />
    </joint>

    <link name="left_wheel_link">
        <visual>
            <geometry>
              <mesh filename="package://mobile_03668/STL/wheels_step-1.STL" scale="0.001 0.001 0.001"/>
            </geometry>
            <origin xyz="-0.198 -0.055 -0.04" rpy="0 0 0"/>
            <material name="orange"/>
        </visual>
        <!--<collision>
            <geometry>
                <cylinder radius="0.05" length="0.04" />
            </geometry>
        </collision>-->
        <xacro:inertial_cylinder mass="0.1" length="0.04" radius="0.05">
            <origin xyz="0.075 -0.22 -0.02" rpy="0 0 0" />
        </xacro:inertial_cylinder>
    </link>

    <transmission name="left_wheel_trans" type="SimpleTransmission">
        <type>transmission_interface/SimpleTransmission</type>
        <actuator name="left_wheel_motor">
            <mechanicalReduction>1</mechanicalReduction>
        </actuator>
        <joint name="left_wheel">
            <hardwareInterface>hardware_interface/VelocityJointInterface</hardwareInterface>
        </joint>
    </transmission>

    <!-- RIGHT WHEEL LINK -->

    <joint name="right_wheel" type="continuous">
        <parent link="base_link" />
        <child link="right_wheel_link" />
        <origin xyz="0 -0.105 0.030" rpy="0 0 -1.57"/>
        <dynamics damping="0.5" friction="100.0" />
    </joint>

    <link name="right_wheel_link">
        <visual>
            <geometry>
              <mesh filename="package://mobile_03668/STL/wheels_step-2.STL" scale="0.001 0.001 0.001"/>
            </geometry>
            <origin xyz="-0.0205 -0.04 -0.04" rpy="0 0 0"/>
            <material name="orange"/>
        </visual>
        <!--<collision>
            <geometry>
                <cylinder radius="0.05" length="0.04" />
            </geometry>
        </collision>-->
        <xacro:inertial_cylinder mass="0.1" length="0.04" radius="0.05">
            <origin xyz="0.075 -0.005 0" rpy="0 0 1.57" />
        </xacro:inertial_cylinder>
    </link>
    <transmission name="right_wheel_trans" type="SimpleTransmission">
        <type>transmission_interface/SimpleTransmission</type>
        <actuator name="right_wheel_motor">
            <mechanicalReduction>1</mechanicalReduction>
        </actuator>
        <joint name="right_wheel">
            <hardwareInterface>hardware_interface/VelocityJointInterface</hardwareInterface>
        </joint>
    </transmission>


    <!--Front
    CASTER WHEEL LINK -->

    <joint name="caster_wheel_joint" type="fixed">
        <parent link="chassis" />
        <child link="caster_wheel" />
        <origin xyz="0 0 0" rpy="0 0 0"/>
        <dynamics damping="0.0" friction="0.0" />
    </joint>

    <gazebo reference="caster_wheel">
        <mu1 value="0.0" />
        <mu2 value="0.0" />
        <kp value="10000000.0" />
        <kd value="1.0" />
        <fdir1 value="1 0 0" />
        <material>Gazebo/Grey</material>
        <turnGravityOff>false</turnGravityOff>
    </gazebo>

    <gazebo reference="left_wheel">
        <mu1 value="100.0" />
        <mu2 value="100.0" />
        <kp value="10000000.0" />
        <kd value="1.0" />
        <fdir1 value="1 0 0" />
        <material>Gazebo/Grey</material>
        <turnGravityOff>false</turnGravityOff>
    </gazebo>

    <gazebo reference="right_wheel">
        <mu1 value="100.0" />
        <mu2 value="100.0" />
        <kp value="10000000.0" />
        <kd value="1.0" />
        <fdir1 value="1 0 0" />
        <material>Gazebo/Grey</material>
        <turnGravityOff>false</turnGravityOff>
    </gazebo>

    <link name="caster_wheel">
        <visual>
            <geometry>
              <mesh filename="package://mobile_03668/STL/FreeBall.STL" scale="0.001 0.001 0.001"/>
            </geometry>
            <origin xyz="-0.15 -0.115 -0.015" rpy="1.57 0 1.57"/>
            <material name="white"/>
        </visual>
        <!--<collision>
            <geometry>
                <sphere radius="0.05" />
            </geometry>
        </collision>-->
        <xacro:inertial_sphere mass="0.1" radius="0.05">
            <origin xyz="0.125 0.15 -0.015" rpy="1.57 0 1.57" />
        </xacro:inertial_sphere>
    </link>

    <!-- Add a Sensor Link -->
    <link name="lidar_link">
        <visual>
            <!-- Visual properties of the lidar sensor -->
            <geometry>
                <cylinder radius="0.02" length="0.02" /> <!-- Example shape, adjust as needed -->
            </geometry>
            <material name="black" /> <!-- Example material, adjust as needed -->
        </visual>
        <!--<collision>
            Collision properties of the lidar sensor
            <geometry>
                <cylinder radius="0.03" length="0.06" />
            </geometry>
        </collision> -->
        <!-- Define inertial properties if necessary -->
    </link>

    <!-- Attach the Sensor to the Robot -->
    <joint name="lidar_joint" type="fixed">
        <parent link="chassis"/>
        <child link="lidar_link"/>
        <origin xyz="0.0105 -0.005 0.199" rpy="0 0 0"/>
    </joint>

    <gazebo>
        <plugin name="gazebo_ros_control" filename="libgazebo_ros_control.so">
            <robotNamespace>$(arg robot_namespace)</robotNamespace>
            <legacyModeNS>true</legacyModeNS>
        </plugin>
    </gazebo>

</robot>
